<?xml version="1.0"?>
<robot name="puma01">
  <origin xyz="0.0 0.0 0.0" rpy="0.0 0.0 0.0"/>

<!-- LINKS -->
  <link name="world"/> 
  <joint name="link_link0" type="fixed">
    <origin xyz="0.0 0.0 0.0" rpy="1.57079632679 0.0 3.14"/>
    <parent link="world"/>
    <child link="link0"/>
  </joint>

  <link name="link0">
    <visual>
      <origin xyz="0.0 0.0 0.0" rpy="0.0 0.0 0.0"/>
      <geometry>
        <mesh filename="package://puma01_description/meshes/link0.dae"/>
      </geometry>
    </visual>
    <collision>
      <origin xyz="0.0 0.0 0.0" rpy="0.0 0.0 0.0"/>
      <geometry>
        <mesh filename="package://puma01_description/meshes/link0.dae"/>
      </geometry>
    </collision>
    <inertial>
      <origin xyz="0.0  0.1925 -0.0219"/>
      <mass value="30.0"/>
      <inertia ixx="1.045642" ixy="0.0" ixz="0.0"  iyy="0.305407" iyz="-0.042116" izz="0.958215"/>
    </inertial>
  </link>
  
  <link name="link1">
    <visual>
      <origin xyz="0.0 0.0 0.0" rpy="0.0 0.0 0.0"/>
      <geometry>
        <mesh filename="package://puma01_description/meshes/link1.dae"/>
      </geometry>
    </visual>
    <collision>
      <origin xyz="0.0 0.0 0.0" rpy="0.0 0.0 0.0"/>
      <geometry>
        <mesh filename="package://puma01_description/meshes/link1.dae"/>
      </geometry>
    </collision>
    <inertial>
      <origin xyz="0.0 0.0225 -0.0028"/>
      <mass value="12"/>
      <inertia ixx="0.073957" ixy="0.0" ixz="0.0"  iyy="0.036037" iyz="-0.000754" izz="0.073514"/>
    </inertial>
  </link>
  
  <link name="link2">
    <visual>
      <origin xyz="0.0 0.0 0.0" rpy="0.0 0.0 0.0"/>
      <geometry>
        <mesh filename="package://puma01_description/meshes/link2.dae"/>
      </geometry>
    </visual>
    <collision>
      <origin xyz="0.0 0.0 0.0" rpy="0.0 0.0 0.0"/>
      <geometry>
        <mesh filename="package://puma01_description/meshes/link2.dae"/>
      </geometry>
    </collision>
    <inertial>
      <origin xyz="0.068 0.006 -0.016"/>
      <mass value="17.4"/>
      <inertia ixx="0.13" ixy="0.0" ixz="0.0"  iyy="0.524" iyz="0.0" izz="0.539"/>
    </inertial>
  </link>
  
  <link name="link3">
    <visual>
      <origin xyz="0.0 0.0 0.0" rpy="0.0 0.0 0.0"/>
      <geometry>
        <mesh filename="package://puma01_description/meshes/link3.dae"/>
      </geometry>
    </visual>
    <collision>
      <origin xyz="0.0 0.0 0.0" rpy="0.0 0.0 0.0"/>
      <geometry>
        <mesh filename="package://puma01_description/meshes/link3.dae"/>
      </geometry>
    </collision>
    <inertial>
      <origin xyz="0.0 -0.07 0.014"/>
      <mass value="4.8"/>
      <inertia ixx="0.076" ixy="0.0" ixz="0.0"  iyy="0.0125" iyz="0.0" izz="0.086"/>
    </inertial>
  </link>
  
  <link name="link4">
    <visual>
      <origin xyz="0.0 0.0 0.0" rpy="0.0 0.0 0.0"/>
      <geometry>
        <mesh filename="package://puma01_description/meshes/link4.dae"/>
      </geometry>
    </visual>
    <collision>
      <origin xyz="0.0 0.0 0.0" rpy="0.0 0.0 0.0"/>
      <geometry>
        <mesh filename="package://puma01_description/meshes/link4.dae"/>
      </geometry>
    </collision>
    <inertial>
      <origin xyz="0.0 0.0 -0.019"/>
      <mass value="0.82"/>
      <inertia ixx="0.0018" ixy="0.0" ixz="0.0"  iyy="0.0018" iyz="0.0" izz="0.0013"/>
    </inertial>
  </link>
  
  <link name="link5">
    <visual>
      <origin xyz="0.0 0.0 0.0" rpy="0.0 0.0 0.0"/>
      <geometry>
        <mesh filename="package://puma01_description/meshes/link5.dae"/>
      </geometry>
    </visual>
      <collision>
      <origin xyz="0.0 0.0 0.0" rpy="0.0 0.0 0.0"/>
      <geometry>
        <mesh filename="package://puma01_description/meshes/link5.dae"/>
      </geometry>
    </collision>
    <inertial>
      <origin xyz="0.0 0.0 0.0"/>
      <mass value="0.34"/>
      <inertia ixx="0.0003" ixy="0.0" ixz="0.0"  iyy="0.0003" iyz="0.0" izz="0.0004"/>
    </inertial>
  </link>
  
  <link name="link6">
    <visual>
      <origin xyz="0.0 0.0 0.0" rpy="0.0 0.0 0.0"/>
      <geometry>
        <mesh filename="package://puma01_description/meshes/link6.dae"/>
      </geometry>
    </visual>
      <collision>
      <origin xyz="0.0 0.0 0.0" rpy="0.0 0.0 0.0"/>
      <geometry>
        <mesh filename="package://puma01_description/meshes/link6.dae"/>
      </geometry>
    </collision>
    <inertial>
      <origin xyz="0.0 0.0 0.032"/>
      <mass value="0.09"/>
      <inertia ixx="0.00015" ixy="0.0" ixz="0.0"  iyy="0.00015" iyz="0.0" izz="0.00004"/>
    </inertial>
  </link>

<!-- ADVANCED LINK PARAMETERS --> 
    
  <gazebo reference="link1">
    <visual>  
      <material>  
        <ambient>255.0 136.0 0.0 1.0</ambient>  
        <diffuse>245.0 155.0 51.0 1.0</diffuse>  
        <specular>232.0 171.0 102.0 1.0</specular>  
        <emissive>1.7 3.8 4.4 1.0</emissive>  
      </material>  
    </visual>
  </gazebo>
  
  <gazebo reference="link2">
    <visual>  
      <material>  
        <ambient>17.0 38.0 44.0 1.0</ambient>  
        <diffuse>17.0 38.0 44.0 1.0</diffuse>  
        <specular>17.0 38.0 44.0 1.0</specular>  
        <emissive>1.7 3.8 4.4 1.0</emissive>  
      </material>  
    </visual>
  </gazebo>
  
  <gazebo reference="link3">
    <visual>  
      <material>  
        <ambient>255.0 136.0 0.0 1.0</ambient>  
        <diffuse>245.0 155.0 51.0 1.0</diffuse>  
        <specular>232.0 171.0 102.0 1.0</specular>  
        <emissive>1.7 3.8 4.4 1.0</emissive>  
      </material>  
    </visual>
  </gazebo>
  
  <gazebo reference="link4">
    <visual>  
      <material>  
        <ambient>17.0 38.0 44.0 1.0</ambient>  
        <diffuse>17.0 38.0 44.0 1.0</diffuse>  
        <specular>17.0 38.0 44.0 1.0</specular>  
        <emissive>1.7 3.8 4.4 1.0</emissive>  
      </material>  
    </visual>
  </gazebo>
  
  <gazebo reference="link5">
    <visual>  
      <material>  
        <ambient>255.0 136.0 0.0 1.0</ambient>  
        <diffuse>245.0 155.0 51.0 1.0</diffuse>  
        <specular>232.0 171.0 102.0 1.0</specular>  
        <emissive>1.7 3.8 4.4 1.0</emissive>  
      </material>  
    </visual>
  </gazebo>
  
  <gazebo reference="link6">
    <visual>  
      <material>  
        <ambient>17.0 38.0 44.0 1.0</ambient>  
        <diffuse>17.0 38.0 44.0 1.0</diffuse>  
        <specular>17.0 38.0 44.0 1.0</specular>  
        <emissive>1.7 3.8 4.4 1.0</emissive>  
      </material>  
    </visual>
    <kp>6000000.0</kp>
    <kd>10.0</kd>
    <mu1>0.9</mu1>
    <mu2>0.9</mu2>
    <fdir1>1 0 0</fdir1>
    <maxVel>0.5</maxVel>
    <minDepth>0.003</minDepth>
    <maxContacts>5</maxContacts>
  </gazebo>

<!-- JOINTS -->    
  <joint name="joint_1" type="revolute">
    <origin xyz="0.0  0.62357 0.0 " rpy="-1.57079632679 -1.57079632679 0.0"/>
    <parent link="link0"/>
    <child link="link1"/>
    <axis xyz="0.0 0.0 1.0"/>
    <dynamics damping="0.5" friction="0.0"/>
    <limit effort="80.0" velocity="5.0" lower="-2.79" upper="2.79" />
  </joint>
  
  <joint name="joint_2" type="revolute">
    <origin xyz="0.0 0.2182 0.0" rpy="-1.57079632679 0.0 0.0"/>
    <parent link="link1"/>
    <child link="link2"/>
    <axis xyz="0.0 0.0 1.0"/>
    <dynamics damping="0.5" friction="0.0"/>
    <limit effort="80.0" velocity="5.0" lower="-3.93" upper="0.78" />
  </joint>
  
  <joint name="joint_3" type="revolute">
    <origin xyz="0.4318 0.0 -0.0889" rpy="0.0 0.0 0.0"/>
    <parent link="link2"/>
    <child link="link3"/>
    <axis xyz="0.0 0.0 1.0"/>
    <dynamics damping="0.5" friction="0.0"/>
    <limit effort="80.0" velocity="5.0" lower="-0.78" upper="3.93" />
  </joint>
    
  <joint name="joint_4" type="revolute">
    <origin xyz="0.0 -0.43202 0.0" rpy="1.57079632679 0.0 0.0"/>
    <parent link="link3"/>
    <child link="link4"/>
    <axis xyz="0.0 0.0 1.0"/>
    <dynamics damping="0.5" friction="0.0"/>
    <limit effort="50.0" velocity="5.0" lower="-1.92" upper="2.97" />
  </joint>
  
  <joint name="joint_5" type="revolute">
    <origin xyz="0.0 0.0 0.0" rpy="-1.57079632679 0.0 0.0"/>
    <parent link="link4"/>
    <child link="link5"/>
    <axis xyz="0.0 0.0 1.0"/>
    <dynamics damping="0.5" friction="0.0"/>
    <limit effort="50.0" velocity="5.0" lower="-1.74" upper="1.74" />
  </joint>
  
  <joint name="joint_6" type="revolute">
    <origin xyz="0.0 0.0 0.0" rpy="1.57079632679 0.0 0.0"/>
    <parent link="link5"/>
    <child link="link6"/>
    <axis xyz="0.0 0.0 1.0"/>
    <dynamics damping="0.5" friction="0.0"/>
    <limit effort="50.0" velocity="5.0" lower="-4.64" upper="4.64" />
  </joint>

