<?xml version="1.0"?>
<robot name="puma01">
  <origin xyz="0.0 0.0 0.0" rpy="0.0 0.0 0.0"/>

<!-- LINKS -->
  <link name="world"/> 
  <joint name="link_link0" type="fixed">
    <!-- <origin xyz="0.0 0.0 0.0" rpy="1.57079632679 0.0 3.14"/> -->
    <origin xyz="0.0 0.0 0.0" rpy="0.0 0.0 0.0"/>
    <parent link="world"/>
    <child link="link0"/>
  </joint>

  <link name="link0">
    <visual>
      <origin xyz="0.0 0.0 0.0" rpy="1.57079632679 0.0 3.14"/>
      <geometry>
        <mesh filename="package://puma01_description/meshes/link0.dae"/>
      </geometry>
    </visual>
    <collision>
      <origin xyz="0.0 0.0 0.0" rpy="1.57079632679 0.0 3.14"/>
      <geometry>
        <mesh filename="package://puma01_description/meshes/link0.dae"/>
      </geometry>
    </collision>
    <inertial>
      <origin xyz="0.0  0.1925 -0.0219" rpy="1.57079632679 0.0 3.14"/>
      <mass value="30.0"/>
      <inertia ixx="1.045642" ixy="0.0" ixz="0.0"  iyy="0.305407" iyz="-0.042116" izz="0.958215"/>
    </inertial>
  </link>
  
  <link name="link1">
    <visual>
      <origin xyz="0.0 0.0 0.0" rpy="0.0 0.0 0.0"/>
      <geometry>
        <mesh filename="package://puma01_description/meshes/link1.dae"/>
      </geometry>
    </visual>
    <collision>
      <origin xyz="0.0 0.0 0.0" rpy="0.0 0.0 0.0"/>
      <geometry>
        <mesh filename="package://puma01_description/meshes/link1.dae"/>
      </geometry>
    </collision>
    <inertial>
      <origin xyz="0.0 0.0225 -0.0028"/>
      <mass value="12"/>
      <inertia ixx="0.073957" ixy="0.0" ixz="0.0"  iyy="0.036037" iyz="-0.000754" izz="0.073514"/>
    </inertial>
  </link>
  
  <link name="link2">
    <visual>
      <origin xyz="0.0 0.0 0.0" rpy="0.0 0.0 0.0"/>
      <geometry>
        <mesh filename="package://puma01_description/meshes/link2.dae"/>
      </geometry>
    </visual>
    <collision>
      <origin xyz="0.0 0.0 0.0" rpy="0.0 0.0 0.0"/>
      <geometry>
        <mesh filename="package://puma01_description/meshes/link2.dae"/>
      </geometry>
    </collision>
    <inertial>
      <origin xyz="0.068 0.006 -0.016"/>
      <mass value="17.4"/>
      <inertia ixx="0.13" ixy="0.0" ixz="0.0"  iyy="0.524" iyz="0.0" izz="0.539"/>
    </inertial>
  </link>
  
  <link name="link3">
    <visual>
      <origin xyz="0.0 0.0 0.0" rpy="0.0 0.0 0.0"/>
      <geometry>
        <mesh filename="package://puma01_description/meshes/link3.dae"/>
      </geometry>
    </visual>
    <collision>
      <origin xyz="0.0 0.0 0.0" rpy="0.0 0.0 0.0"/>
      <geometry>
        <mesh filename="package://puma01_description/meshes/link3.dae"/>
      </geometry>
    </collision>
    <inertial>
      <origin xyz="0.0 -0.07 0.014"/>
      <mass value="4.8"/>
      <inertia ixx="0.076" ixy="0.0" ixz="0.0"  iyy="0.0125" iyz="0.0" izz="0.086"/>
    </inertial>
  </link>
  
  <link name="link4">
    <visual>
      <origin xyz="0.0 0.0 0.0" rpy="0.0 0.0 0.0"/>
      <geometry>
        <mesh filename="package://puma01_description/meshes/link4.dae"/>
      </geometry>
    </visual>
    <collision>
      <origin xyz="0.0 0.0 0.0" rpy="0.0 0.0 0.0"/>
      <geometry>
        <mesh filename="package://puma01_description/meshes/link4.dae"/>
      </geometry>
    </collision>
    <inertial>
      <origin xyz="0.0 0.0 -0.019"/>
      <mass value="0.82"/>
      <inertia ixx="0.0018" ixy="0.0" ixz="0.0"  iyy="0.0018" iyz="0.0" izz="0.0013"/>
    </inertial>
  </link>
  
  <link name="link5">
    <visual>
      <origin xyz="0.0 0.0 0.0" rpy="0.0 0.0 0.0"/>
      <geometry>
        <mesh filename="package://puma01_description/meshes/link5.dae"/>
      </geometry>
    </visual>
      <collision>
      <origin xyz="0.0 0.0 0.0" rpy="0.0 0.0 0.0"/>
      <geometry>
        <mesh filename="package://puma01_description/meshes/link5.dae"/>
      </geometry>
    </collision>
    <inertial>
      <origin xyz="0.0 0.0 0.0"/>
      <mass value="0.34"/>
      <inertia ixx="0.0003" ixy="0.0" ixz="0.0"  iyy="0.0003" iyz="0.0" izz="0.0004"/>
    </inertial>
  </link>
  
  <link name="link6">
    <visual>
      <origin xyz="0.0 0.0 0.0" rpy="0.0 0.0 0.0"/>
      <geometry>
        <mesh filename="package://puma01_description/meshes/link6.dae"/>
      </geometry>
    </visual>
      <collision>
      <origin xyz="0.0 0.0 0.0" rpy="0.0 0.0 0.0"/>
      <geometry>
        <mesh filename="package://puma01_description/meshes/link6.dae"/>
      </geometry>
    </collision>
    <inertial>
      <origin xyz="0.0 0.0 0.032"/>
      <mass value="0.09"/>
      <inertia ixx="0.00015" ixy="0.0" ixz="0.0"  iyy="0.00015" iyz="0.0" izz="0.00004"/>
    </inertial>
  </link>

  <link name="link_T">
    <inertial>
      <mass value="0.001"/>
      <origin rpy="0  0  0" xyz="0  0  0.05"/>
      <inertia ixx="0" ixy="0" ixz="0" iyy="0" iyz="0" izz="0"/>                    
    </inertial>
    <visual>
      <origin rpy="0  0  0" xyz="0 0 0.05"/>
      <geometry>
        <cylinder length="0.1" radius="0.01"/> 
      </geometry>
    </visual>
    <collision>
      <origin rpy="0  0 0" xyz="0 0 0.05"/>
      <geometry>
        <cylinder length="0.1" radius="0.01"/>
      </geometry>
    </collision>
  </link>

<!-- ADVANCED LINK PARAMETERS --> 
    
  <gazebo reference="link1">
    <visual>  
      <material>  
        <ambient>255.0 136.0 0.0 1.0</ambient>  
        <diffuse>245.0 155.0 51.0 1.0</diffuse>  
        <specular>232.0 171.0 102.0 1.0</specular>  
        <emissive>1.7 3.8 4.4 1.0</emissive>  
      </material>  
    </visual>
  </gazebo>
  
  <gazebo reference="link2">
    <visual>  
      <material>  
        <ambient>17.0 38.0 44.0 1.0</ambient>  
        <diffuse>17.0 38.0 44.0 1.0</diffuse>  
        <specular>17.0 38.0 44.0 1.0</specular>  
        <emissive>1.7 3.8 4.4 1.0</emissive>  
      </material>  
    </visual>
  </gazebo>
  
  <gazebo reference="link3">
    <visual>  
      <material>  
        <ambient>255.0 136.0 0.0 1.0</ambient>  
        <diffuse>245.0 155.0 51.0 1.0</diffuse>  
        <specular>232.0 171.0 102.0 1.0</specular>  
        <emissive>1.7 3.8 4.4 1.0</emissive>  
      </material>  
    </visual>
  </gazebo>
  
  <gazebo reference="link4">
    <visual>  
      <material>  
        <ambient>17.0 38.0 44.0 1.0</ambient>  
        <diffuse>17.0 38.0 44.0 1.0</diffuse>  
        <specular>17.0 38.0 44.0 1.0</specular>  
        <emissive>1.7 3.8 4.4 1.0</emissive>  
      </material>  
    </visual>
  </gazebo>
  
  <gazebo reference="link5">
    <visual>  
      <material>  
        <ambient>255.0 136.0 0.0 1.0</ambient>  
        <diffuse>245.0 155.0 51.0 1.0</diffuse>  
        <specular>232.0 171.0 102.0 1.0</specular>  
        <emissive>1.7 3.8 4.4 1.0</emissive>  
      </material>  
    </visual>
  </gazebo>
  
  <gazebo reference="link6">
    <visual>  
      <material>  
        <ambient>17.0 38.0 44.0 1.0</ambient>  
        <diffuse>17.0 38.0 44.0 1.0</diffuse>  
        <specular>17.0 38.0 44.0 1.0</specular>  
        <emissive>1.7 3.8 4.4 1.0</emissive>  
      </material>  
    </visual>
  </gazebo>

  <gazebo reference="link_T">
      <visual>  
      <material>  
        <ambient>17.0 38.0 44.0 1.0</ambient>  
        <diffuse>17.0 38.0 44.0 1.0</diffuse>  
        <specular>17.0 38.0 44.0 1.0</specular>  
        <emissive>1.7 3.8 4.4 1.0</emissive>  
      </material>  
    </visual>
    <kp>600.0</kp>
    <kd>200.0</kd>
    <mu1>0.9</mu1>
    <mu2>0.9</mu2>
    <fdir1>1 0 0</fdir1>
    <maxVel>0.5</maxVel>
    <minDepth>0.003</minDepth>
    <maxContacts>5</maxContacts>
    <gravity>false</gravity>
  </gazebo>

<!-- JOINTS -->    
  <joint name="joint_1" type="revolute">
    <origin xyz="0.0  0.0 0.62357" rpy="0.0 0.0 0.0"/>
    <parent link="link0"/>
    <child link="link1"/>
    <axis xyz="0.0 0.0 1.0"/>
    <dynamics damping="0.5" friction="0.0"/>
    <!-- angle range = 5.585 -->
    <limit effort="150.0" velocity="10.0" lower="-2.79" upper="2.79" />
  </joint>
  
  <joint name="joint_2" type="revolute">
    <origin xyz="0.0 0.2182 0.0" rpy="-1.57079632679 -1.57079632679 0.0"/>
    <parent link="link1"/>
    <child link="link2"/>
    <axis xyz="0.0 0.0 1.0"/>
    <dynamics damping="0.5" friction="0.0"/>
    <!-- angle range = 4.6425 -->
    <limit effort="150.0" velocity="10.0" lower="-2.32" upper="2.32" />   
  </joint>
  
  <joint name="joint_3" type="revolute">
    <origin xyz="0.4318 0.0 -0.0889" rpy="0.0 0.0 1.57079632679"/>
    <parent link="link2"/>
    <child link="link3"/>
    <axis xyz="0.0 0.0 1.0"/>
    <dynamics damping="0.5" friction="0.0"/>
    <!-- angle range = 4.9567 -->
    <limit effort="150.0" velocity="10.0" lower="-2.478" upper="2.478" />
  </joint>
    
  <joint name="joint_4" type="revolute">
    <origin xyz="0.0 -0.43202 0.0" rpy="1.57079632679 0.0 0.0"/>
    <parent link="link3"/>
    <child link="link4"/>
    <axis xyz="0.0 0.0 1.0"/>
    <!-- angle range = 4.8869 -->
    <limit effort="150.0" velocity="10.0" lower="-1.92" upper="2.97" /> <!-- ???? -->
  </joint>
  
  <joint name="joint_5" type="revolute">
    <origin xyz="0.0 0.0 0.0" rpy="-1.57079632679 0.0 0.0"/>
    <parent link="link4"/>
    <child link="link5"/>
    <axis xyz="0.0 0.0 1.0"/>
    <!-- angle range = 3.4906 -->
    <limit effort="150.0" velocity="10.0" lower="-1.74" upper="1.74" />
  </joint>
  
  <joint name="joint_6" type="revolute">
    <origin xyz="0.0 0.0 0.0" rpy="1.57079632679 0.0 0.0"/>
    <parent link="link5"/>
    <child link="link6"/>
    <axis xyz="0.0 0.0 1.0"/>
   <!-- angle range = 9.2851 -->
    <limit effort="150.0" velocity="10.0" lower="-4.64" upper="4.64" /> <!-- ???? -->
  </joint>

  <joint name="joint_6_T" type="revolute">
    <origin xyz="0.0 0.0 0.05334" rpy="0 0 0"/>
    <parent link="link6"/>
    <child link="link_T"/>
    <axis xyz="0.0 0.0 1.0"/>
    <dynamics damping="0.0" friction="0.0"/>
    <limit effort="1.0" velocity="1.0" lower="0" upper="0" />
  </joint>

<!-- ROS CONTROL -->   
  <gazebo>
    <plugin name="gazebo_ros_control" filename="libgazebo_ros_control.so">
    <!-- namespace for simulation -->
    <robotNamespace>/puma01_sim</robotNamespace>
    <legacyModeNS>true</legacyModeNS>
    <robotBaseFrame>link0</robotBaseFrame>
    </plugin>
  </gazebo>

<!-- TRANSMISSIONS -->     
  <transmission name="trans_1">
    <type>transmission_interface/SimpleTransmission</type>
    <joint name="joint_1">
      <hardwareInterface>hardware_interface/EffortJointInterface</hardwareInterface>
    </joint>
    <actuator name="motor_1">
      <mechanicalReduction>1</mechanicalReduction>
    </actuator>
  </transmission>
  
  <transmission name="trans_2">
    <type>transmission_interface/SimpleTransmission</type>
    <joint name="joint_2">
      <hardwareInterface>hardware_interface/EffortJointInterface</hardwareInterface>
    </joint>
    <actuator name="motor_2">
      <mechanicalReduction>1</mechanicalReduction>
    </actuator>
  </transmission>
  
  <transmission name="trans_3">
    <type>transmission_interface/SimpleTransmission</type>
    <joint name="joint_3">
      <hardwareInterface>hardware_interface/EffortJointInterface</hardwareInterface>
    </joint>
    <actuator name="motor_3">
      <mechanicalReduction>1</mechanicalReduction>
    </actuator>
  </transmission>
  
  <transmission name="trans_4">
    <type>transmission_interface/SimpleTransmission</type>
    <joint name="joint_4">
      <hardwareInterface>hardware_interface/EffortJointInterface</hardwareInterface>
    </joint>
    <actuator name="motor_4">
      <mechanicalReduction>1</mechanicalReduction>
    </actuator>
  </transmission>
  
  <transmission name="trans_5">
    <type>transmission_interface/SimpleTransmission</type>
    <joint name="joint_5">
      <hardwareInterface>hardware_interface/EffortJointInterface</hardwareInterface>
    </joint>
    <actuator name="motor_5">
      <mechanicalReduction>1</mechanicalReduction>
    </actuator>
  </transmission>
  
  <transmission name="trans_6">
    <type>transmission_interface/SimpleTransmission</type>
    <joint name="joint_6">
      <hardwareInterface>hardware_interface/EffortJointInterface</hardwareInterface>
    </joint>
    <actuator name="motor_6">
      <mechanicalReduction>1</mechanicalReduction>
    </actuator>
  </transmission>
 
<!-- FORCE/TORQUE SENSOR -->     
  <gazebo reference="joint_6_T">
    <provideFeedback>true</provideFeedback>
  </gazebo>
      
  <gazebo>
    <plugin name="joint_6_T_ft_sensor" filename="libgazebo_ros_ft_sensor.so">
      <updateRate>80</updateRate>
      <topicName>/puma01_sim/ft_sensor</topicName> 
      <jointName>joint_6_T</jointName>
      <force_torque>
        <frame>child</frame>
        <measure_direction>child_to_parent</measure_direction>
      </force_torque>
      <noise>
        <type>gaussian</type>
        <mean>0.0</mean>
        <stddev>0.0</stddev> 
      </noise>
    </plugin>
  </gazebo>
  
</robot>
